#VRML_SIM R2019a utf8
WorldInfo {
}
Viewpoint {
  orientation -0.02142907343354662 -0.9923820502146394 -0.1213204897103882 2.794545633391014
  position -0.2401704785582962 0.940329007128328 -1.607111574465076
}
TexturedBackground {
}
TexturedBackgroundLight {
}
Floor {
}
Solid {
  translation -0.009659855687357943 0 -0.034079142655929096
  children [
    Group {
      children [
        DEF A Group {
          children [
            Transform {
              translation 0 0.356 0
              rotation 1 0 0 0.5235996938995747
              children [
                DEF Cylinder Shape {
                  appearance PBRAppearance {
                    baseColor 0.7568627450980392 0.49019607843137253 0.06666666666666667
                    roughness 1
                    metalness 0
                  }
                  geometry Cylinder {
                    height 0.7999999999999999
                    radius 0.03
                  }
                }
              ]
            }
            Transform {
              translation 0 0.358 0.4
              rotation 1 0 0 -0.5236003061004253
              children [
                USE Cylinder
              ]
            }
            Transform {
              translation 0 0.27 0.19000000004794895
              rotation 1 0 0 1.5707963220000003
              children [
                Shape {
                  appearance PBRAppearance {
                    baseColor 0.6431372549019608 0 0
                    roughness 1
                    metalness 0
                  }
                  geometry Cylinder {
                    height 0.5
                    radius 0.019999999999999997
                  }
                }
              ]
            }
          ]
        }
        Transform {
          translation 1 0 0
          children [
            USE A
          ]
        }
        Solid {
          translation 0.5 0.6900000000000001 0.19999999999999998
          rotation -0.5773502620877834 -0.5773502692801284 0.5773502762009656 4.188790204514883
          children [
            Shape {
              appearance PBRAppearance {
                baseColor 0.8 0 0
                roughness 1
                metalness 0
              }
              geometry Cylinder {
                height 1
                radius 0.03
              }
            }
            HingeJoint {
              jointParameters HingeJointParameters {
                position -182967.22904368147
                axis 0 0 1
                staticFriction 0.02
              }
              endPoint Solid {
                translation -3.001445704564942e-13 -1.3189172658467266e-13 0.0400313919999999
                rotation 7.224323875513428e-12 -1.5416633859105727e-11 -1 5.558965310973117
                children [
                  Shape {
                    appearance PBRAppearance {
                      baseColor 0.7568627450980392 0.49019607843137253 0.06666666666666667
                      roughness 1
                      metalness 0.9
                    }
                    geometry Box {
                      size 0.4 0.1 0.019999999999999997
                    }
                  }
                  HingeJoint {
                    jointParameters HingeJointParameters {
                      position 1.2486360549943527
                    }
                    endPoint Solid {
                      translation 2.0816681711721697e-17 -0.15176858470525684 0.050658629043463806
                      rotation 1 4.665242208945654e-18 -3.4321168730874e-16 2.819432376994353
                      children [
                        Shape {
                          appearance PBRAppearance {
                            baseColor 0.9882352941176471 0.9137254901960784 0.30980392156862746
                            roughness 1
                            metalness 0
                          }
                          geometry Cylinder {
                            height 0.30000000000000004
                            radius 0.03
                          }
                        }
                        Solid {
                          translation 0 0.18 0
                          children [
                            Shape {
                              geometry Sphere {
                                radius 0.05
                              }
                            }
                          ]
                        }
                      ]
                      physics Physics {
                      }
                      linearVelocity 0.11748196433702891 -0.027096227354639423 -0.12436968965966907
                      angularVelocity -0.1126137063566928 -1.118378821571776 0.13860548802676925
                    }
                  }
                ]
                physics Physics {
                }
                linearVelocity 4.453303744334922e-07 3.3375091845771416e-08 -7.348189190584623e-07
                angularVelocity 2.2127192157350704e-06 -1.1182311119867223 1.3094625073527458e-06
              }
            }
          ]
        }
      ]
    }
  ]
}
