#VRML_SIM R2019a utf8
WorldInfo {
}
Viewpoint {
  orientation 0.00521809467210252 -0.9990468547347923 0.04333766874800523 2.9021615581422338
  position -0.192432897264339 0.3294161281479108 -1.5917477508855131
}
TexturedBackground {
}
TexturedBackgroundLight {
}
Floor {
}
Solid {
  translation -0.009659855687357943 0 -0.034079142655929096
  children [
    Group {
      children [
        DEF A Group {
          children [
            Transform {
              translation 0 0.356 0
              rotation 1 0 0 0.5235996938995747
              children [
                DEF Cylinder Shape {
                  appearance PBRAppearance {
                    baseColor 0.7568627450980392 0.49019607843137253 0.06666666666666667
                    roughness 1
                    metalness 0
                  }
                  geometry Cylinder {
                    height 0.7999999999999999
                    radius 0.03
                  }
                }
              ]
            }
            Transform {
              translation 0 0.358 0.4
              rotation 1 0 0 -0.5236003061004253
              children [
                USE Cylinder
              ]
            }
            Transform {
              translation 0 0.27 0.19000000004794895
              rotation 1 0 0 1.5707963220000003
              children [
                Shape {
                  appearance PBRAppearance {
                    baseColor 0.6431372549019608 0 0
                    roughness 1
                    metalness 0
                  }
                  geometry Cylinder {
                    height 0.5
                    radius 0.019999999999999997
                  }
                }
              ]
            }
          ]
        }
        Transform {
          translation 1 0 0
          children [
            USE A
          ]
        }
        Solid {
          translation 0.5 0.6900000000000001 0.19999999999999998
          rotation -0.5773502620877834 -0.5773502692801284 0.5773502762009656 4.188790204514883
          children [
            Shape {
              appearance PBRAppearance {
                baseColor 0.8 0 0
                roughness 1
                metalness 0
              }
              geometry Cylinder {
                height 1
                radius 0.03
              }
            }
            HingeJoint {
              jointParameters HingeJointParameters {
                position -182953.49285727367
                axis 0 0 1
                staticFriction 0.02
              }
              endPoint Solid {
                translation 4.277090444998925e-15 -3.27816865358274e-13 0.0400313919999999
                rotation 6.343758356234672e-12 -3.869084152691131e-12 -1 4.389149517534785
                children [
                  Shape {
                    appearance PBRAppearance {
                      baseColor 0.7568627450980392 0.49019607843137253 0.06666666666666667
                      roughness 1
                      metalness 0.9
                    }
                    geometry Box {
                      size 0.4 0.1 0.019999999999999997
                    }
                  }
                  HingeJoint {
                    jointParameters HingeJointParameters {
                      position 1.3194062626728116
                    }
                    endPoint Solid {
                      translation 2.081668171172169e-17 -0.15497081253598752 0.03980009123024467
                      rotation 0.9999999999999999 1.6718727701959172e-17 -3.410846016037048e-16 2.890202584672812
                      children [
                        Shape {
                          appearance PBRAppearance {
                            baseColor 0.9882352941176471 0.9137254901960784 0.30980392156862746
                            roughness 1
                            metalness 0
                          }
                          geometry Cylinder {
                            height 0.30000000000000004
                            radius 0.03
                          }
                        }
                      ]
                      physics Physics {
                      }
                      linearVelocity -0.10911698224643539 -6.831004951803784e-10 -0.039786944805889436
                      angularVelocity -2.49355234277819e-09 0.7484421236744861 -6.0155376612153786e-09
                    }
                  }
                ]
                physics Physics {
                }
                linearVelocity -3.0890060736875624e-08 1.1369355824107434e-15 -9.539580870393075e-09
                angularVelocity -2.3557630620125206e-09 0.7484421236744134 -5.965281070938052e-09
              }
            }
          ]
        }
      ]
    }
  ]
}
